<?xml version="1.0" ?>
<!-- =================================================================================== -->
<!-- |    This document was autogenerated by xacro from car.xacro                      | -->
<!-- |    EDITING THIS FILE BY HAND IS NOT RECOMMENDED                                 | -->
<!-- =================================================================================== -->
<robot name="car">
  <link name="base_link">
    <visual>
      <geometry>
        <mesh filename="package://awesome_driver/meshes/main_frame.obj"/>
      </geometry>
    </visual>
  </link>
  <joint name="caster_joint" type="fixed">
    <parent link="base_link"/>
    <child link="caster"/>
    <origin rpy="0 0 0" xyz="0.28 0 0"/>
  </joint>
  <link name="caster">
    <visual>
      <geometry>
        <sphere radius="0.01"/>
      </geometry>
    </visual>
    <collision>
      <geometry>
        <sphere radius="0.01"/>
      </geometry>
    </collision>
  </link>
  <link name="left_motor">
    <visual>
      <geometry>
        <mesh filename="package://awesome_driver/meshes/rear_actuator.stl"/>
      </geometry>
      <material name="gray">
        <color rgba="0.8 0.8 0.8 1"/>
      </material>
    </visual>
  </link>
  <link name="left_wheel">
    <visual>
      <geometry>
        <mesh filename="package://awesome_driver/meshes/left_rear_wheel.stl"/>
      </geometry>
      <material name="black">
        <color rgba="0.2 0.2 0.2 1"/>
      </material>
    </visual>
    <collision>
      <geometry>
        <cylinder length="0.0265" radius="0.03448"/>
      </geometry>
      <origin rpy="1.570796326795 0 0" xyz="0 0 0"/>
    </collision>
  </link>
  <joint name="left_motor_mnt" type="fixed">
    <parent link="base_link"/>
    <child link="left_motor"/>
    <origin rpy="0 0 0" xyz="0 0.0556 0.0195"/>
  </joint>
  <joint name="left_motor_wheel" type="continuous">
    <parent link="left_motor"/>
    <child link="left_wheel"/>
    <axis xyz="0 1 0"/>
    <origin rpy="0 0 0" xyz="0 0.0264 -0.007"/>
  </joint>
  <link name="right_motor">
    <visual>
      <geometry>
        <mesh filename="package://awesome_driver/meshes/rear_actuator.stl"/>
      </geometry>
      <material name="gray">
        <color rgba="0.8 0.8 0.8 1"/>
      </material>
    </visual>
  </link>
  <link name="right_wheel">
    <visual>
      <geometry>
        <mesh filename="package://awesome_driver/meshes/left_rear_wheel.stl"/>
      </geometry>
      <material name="black">
        <color rgba="0.2 0.2 0.2 1"/>
      </material>
    </visual>
    <collision>
      <geometry>
        <cylinder length="0.0265" radius="0.03448"/>
      </geometry>
      <origin rpy="1.570796326795 0 0" xyz="0 0 0"/>
    </collision>
  </link>
  <joint name="right_motor_mnt" type="fixed">
    <parent link="base_link"/>
    <child link="right_motor"/>
    <origin rpy="0 0 3.14159265359" xyz="0 -0.0556 0.0195"/>
  </joint>
  <joint name="right_motor_wheel" type="continuous">
    <parent link="right_motor"/>
    <child link="right_wheel"/>
    <axis xyz="0 1 0"/>
    <origin rpy="0 0 0" xyz="0 0.0264 -0.007"/>
  </joint>
</robot>

