<?xml version="1.0" ?>
<!-- =================================================================================== -->
<!-- |    This document was autogenerated by xacro from car.xacro                      | -->
<!-- |    EDITING THIS FILE BY HAND IS NOT RECOMMENDED                                 | -->
<!-- =================================================================================== -->
<robot name="car">
  <link name="base_link">
    <visual>
      <geometry>
        <mesh filename="package://awesome_driver/meshes/main_frame.obj"/>
      </geometry>
    </visual>
    <inertial>
      <origin rpy="0.0 0.0 0.0" xyz="0.151 0 0.031"/>
      <!-- <mass value="0.618" /> -->
      <mass value="0.1236"/>
      <!-- <inertia ixx="0.001" ixy="0" ixz="0.001" iyy="0.008" iyz="0" izz="0.008" /> -->
      <inertia ixx="0.002" ixy="0" ixz="0.002" iyy="0.016" iyz="0" izz="0.016"/>
    </inertial>
  </link>
  <gazebo reference="base_link">
    <pose>0 0 0.3 0 0 0</pose>
  </gazebo>
  <joint name="caster_joint" type="fixed">
    <parent link="base_link"/>
    <child link="caster"/>
    <origin rpy="0 0 0" xyz="0.28 0 0"/>
  </joint>
  <link name="caster">
    <visual>
      <geometry>
        <sphere radius="0.01"/>
      </geometry>
    </visual>
    <collision>
      <geometry>
        <sphere radius="0.01"/>
      </geometry>
    </collision>
    <inertial>
      <origin rpy="0 0 0" xyz="0 0 0"/>
      <mass value="0.1"/>
      <inertia ixx="4.000000000000001e-06" ixy="0.0" ixz="0.0" iyy="4.000000000000001e-06" iyz="0.0" izz="4.000000000000001e-06"/>
    </inertial>
  </link>
  <gazebo reference="caster">
    <mu>0.0</mu>
    <mu2>0.0</mu2>
    <slip1>1.0</slip1>
    <slip2>1.0</slip2>
    <material>Gazebo/RedBright</material>
  </gazebo>
  <link name="left_motor">
    <visual>
      <geometry>
        <mesh filename="package://awesome_driver/meshes/rear_actuator.stl"/>
      </geometry>
      <material name="gray">
        <color rgba="0.8 0.8 0.8 1"/>
      </material>
    </visual>
    <inertial>
      <origin rpy="0.0 0.0 0.0" xyz="-3.377e-5 -0.022 -2.101e-4"/>
      <mass value="0.12"/>
      <inertia ixx="3.318e-5" ixy="-1.126e-7" ixz="0" iyy="1.793e-5" iyz="6.885e-7" izz="3.306e-5"/>
    </inertial>
  </link>
  <link name="left_wheel">
    <visual>
      <geometry>
        <mesh filename="package://awesome_driver/meshes/left_rear_wheel.stl"/>
      </geometry>
      <material name="black">
        <color rgba="0.2 0.2 0.2 1"/>
      </material>
    </visual>
    <collision>
      <geometry>
        <cylinder length="0.0265" radius="0.03448"/>
      </geometry>
      <origin rpy="1.570796326795 0 0" xyz="0 0 0"/>
    </collision>
    <inertial>
      <origin rpy="0.0 0.0 0.0" xyz="0 1.707e-4 7.239e-5"/>
      <mass value="0.078"/>
      <inertia ixx="3.101e-5" ixy="0" ixz="0" iyy="5.337e-5" iyz="0" izz="3.095e-5"/>
    </inertial>
  </link>
  <joint name="left_motor_mnt" type="fixed">
    <parent link="base_link"/>
    <child link="left_motor"/>
    <origin rpy="0 0 0" xyz="0 0.0556 0.0195"/>
  </joint>
  <joint name="left_motor_wheel" type="continuous">
    <parent link="left_motor"/>
    <child link="left_wheel"/>
    <axis xyz="0 1 0"/>
    <origin rpy="0 0 0" xyz="0 0.0264 -0.007"/>
  </joint>
  <gazebo reference="left_motor">
    <material>Gazebo/Gold</material>
  </gazebo>
  <gazebo reference="left_wheel">
    <mu>5</mu>
    <mu2>5</mu2>
    <fdir1>1 0 0</fdir1>
    <dampingFactor>0.005</dampingFactor>
    <minDepth>0</minDepth>
    <maxVel>0.1</maxVel>
    <material>Gazebo/Grey</material>
  </gazebo>
  <link name="right_motor">
    <visual>
      <geometry>
        <mesh filename="package://awesome_driver/meshes/rear_actuator.stl"/>
      </geometry>
      <material name="gray">
        <color rgba="0.8 0.8 0.8 1"/>
      </material>
    </visual>
    <inertial>
      <origin rpy="0.0 0.0 0.0" xyz="-3.377e-5 -0.022 -2.101e-4"/>
      <mass value="0.12"/>
      <inertia ixx="3.318e-5" ixy="-1.126e-7" ixz="0" iyy="1.793e-5" iyz="6.885e-7" izz="3.306e-5"/>
    </inertial>
  </link>
  <link name="right_wheel">
    <visual>
      <geometry>
        <mesh filename="package://awesome_driver/meshes/left_rear_wheel.stl"/>
      </geometry>
      <material name="black">
        <color rgba="0.2 0.2 0.2 1"/>
      </material>
    </visual>
    <collision>
      <geometry>
        <cylinder length="0.0265" radius="0.03448"/>
      </geometry>
      <origin rpy="1.570796326795 0 0" xyz="0 0 0"/>
    </collision>
    <inertial>
      <origin rpy="0.0 0.0 0.0" xyz="0 1.707e-4 7.239e-5"/>
      <mass value="0.078"/>
      <inertia ixx="3.101e-5" ixy="0" ixz="0" iyy="5.337e-5" iyz="0" izz="3.095e-5"/>
    </inertial>
  </link>
  <joint name="right_motor_mnt" type="fixed">
    <parent link="base_link"/>
    <child link="right_motor"/>
    <origin rpy="0 0 3.14159265359" xyz="0 -0.0556 0.0195"/>
  </joint>
  <joint name="right_motor_wheel" type="continuous">
    <parent link="right_motor"/>
    <child link="right_wheel"/>
    <axis xyz="0 1 0"/>
    <origin rpy="0 0 0" xyz="0 0.0264 -0.007"/>
  </joint>
  <gazebo reference="right_motor">
    <material>Gazebo/Gold</material>
  </gazebo>
  <gazebo reference="right_wheel">
    <mu>5</mu>
    <mu2>5</mu2>
    <fdir1>1 0 0</fdir1>
    <dampingFactor>0.005</dampingFactor>
    <minDepth>0</minDepth>
    <maxVel>0.1</maxVel>
    <material>Gazebo/Grey</material>
  </gazebo>
</robot>

